<?xml version='1.0' encoding='utf-8'?>
<robot name="sukinee_urdf">
  <link name="world" />
  <joint name="world_to_base_link" type="fixed">
    <parent link="world" />
    <child link="base_link" />
    <origin xyz="0 0 0.0" rpy="0 0 0" />
  </joint>
  <link name="base_link">
    <inertial>
      <origin xyz="1.5245E-07 1.2552E-07 0.013027" rpy="0 0 0" />
      <mass value="0.54275" />
      <inertia ixx="0.00058688" ixy="-2.8116E-05" ixz="1.5174E-09" iyy="0.00028904" iyz="1.2494E-09" izz="0.00073167" />
    </inertial>
    <visual>
      <origin xyz="0 0 0" rpy="0 0 0" />
      <geometry>
        <mesh filename="package://sukinee_urdf/meshes/urdf_camera_gripper/base_link.STL" />
      </geometry>
      <material name="">
        <color rgba="0.69804 0.69804 0.69804 1" />
      </material>
    </visual>
    <collision>
      <origin xyz="0 0 0" rpy="0 0 0" />
      <geometry>
        <mesh filename="package://sukinee_urdf/meshes/urdf_camera_gripper/base_link.STL" />
      </geometry>
    </collision>
  </link>
  <link name="Link1">
    <inertial>
      <origin xyz="-0.0053771 -0.0011385 0.038552" rpy="0 0 0" />
      <mass value="0.37961" />
      <inertia ixx="0.00019575" ixy="6.0614E-06" ixz="2.553E-06" iyy="0.00016059" iyz="4.2618E-07" izz="0.00019169" />
    </inertial>
    <visual>
      <origin xyz="0 0 0" rpy="0 0 0" />
      <geometry>
        <mesh filename="package://sukinee_urdf/meshes/urdf_camera_gripper/Link1.STL" />
      </geometry>
      <material name="">
        <color rgba="0.89804 0.91765 0.92941 1" />
      </material>
    </visual>
    <collision>
      <origin xyz="0 0 0" rpy="0 0 0" />
      <geometry>
        <mesh filename="package://sukinee_urdf/meshes/urdf_camera_gripper/Link1.STL" />
      </geometry>
    </collision>
  </link>
  <joint name="Joint1" type="continuous">
    <origin xyz="0 0 0.0514" rpy="0 0 0" />
    <parent link="base_link" />
    <child link="Link1" />
    <axis xyz="0 0 -1" />
    <limit effort="5" velocity="5" />
  </joint>
  <link name="Link2">
    <inertial>
      <origin xyz="0.19861 -0.019415 -0.027112" rpy="0 0 0" />
      <mass value="0.63265" />
      <inertia ixx="0.00023073" ixy="0.00021283" ixz="-2.0428E-06" iyy="0.0020677" iyz="-3.5072E-07" izz="0.0021179" />
    </inertial>
    <visual>
      <origin xyz="0 0 0" rpy="0 0 0" />
      <geometry>
        <mesh filename="package://sukinee_urdf/meshes/urdf_camera_gripper/Link2.STL" />
      </geometry>
      <material name="">
        <color rgba="0.89804 0.91765 0.92941 1" />
      </material>
    </visual>
    <collision>
      <origin xyz="0 0 0" rpy="0 0 0" />
      <geometry>
        <mesh filename="package://sukinee_urdf/meshes/urdf_camera_gripper/Link2.STL" />
      </geometry>
    </collision>
  </link>
  <joint name="Joint2" type="revolute">
    <origin xyz="-0.010939 0.025949 0.0425" rpy="-1.5708 -0.00097565 0.16603" />
    <parent link="Link1" />
    <child link="Link2" />
    <axis xyz="0 0 -1" />
    <limit lower="-0.3" upper="2.6" effort="5" velocity="5" />
  </joint>
  <link name="Link3">
    <inertial>
      <origin xyz="-0.16918 -0.04234 -0.027922" rpy="0 0 0" />
      <mass value="0.50027" />
      <inertia ixx="0.00012507" ixy="-9.8555E-06" ixz="-6.0131E-07" iyy="0.0010627" iyz="-6.7669E-07" izz="0.0011221" />
    </inertial>
    <visual>
      <origin xyz="0 0 0" rpy="0 0 0" />
      <geometry>
        <mesh filename="package://sukinee_urdf/meshes/urdf_camera_gripper/Link3.STL" />
      </geometry>
      <material name="">
        <color rgba="0.69804 0.69804 0.69804 1" />
      </material>
    </visual>
    <collision>
      <origin xyz="0 0 0" rpy="0 0 0" />
      <geometry>
        <mesh filename="package://sukinee_urdf/meshes/urdf_camera_gripper/Link3.STL" />
      </geometry>
    </collision>
  </link>
  <joint name="Joint3" type="revolute">
    <origin xyz="0.26466 -0.031009 0" rpy="0 0 0" />
    <parent link="Link2" />
    <child link="Link3" />
    <axis xyz="0 0 -1" />
    <limit lower="-2.36" upper="0.3" effort="5" velocity="5" />
  </joint>
  <link name="Link4">
    <inertial>
      <origin xyz="-0.052455 -0.054524 -0.025682" rpy="0 0 0" />
      <mass value="0.27416" />
      <inertia ixx="0.00012695" ixy="-2.6532E-05" ixz="2.2452E-07" iyy="0.00018079" iyz="1.7982E-08" izz="0.00012597" />
    </inertial>
    <visual>
      <origin xyz="0 0 0" rpy="0 0 0" />
      <geometry>
        <mesh filename="package://sukinee_urdf/meshes/urdf_camera_gripper/Link4.STL" />
      </geometry>
      <material name="">
        <color rgba="0.89804 0.91765 0.92941 1" />
      </material>
    </visual>
    <collision>
      <origin xyz="0 0 0" rpy="0 0 0" />
      <geometry>
        <mesh filename="package://sukinee_urdf/meshes/urdf_camera_gripper/Link4.STL" />
      </geometry>
    </collision>
  </link>
  <joint name="Joint4" type="revolute">
    <origin xyz="-0.25553 -0.046044 -0.0039" rpy="0 0 0" />
    <parent link="Link3" />
    <child link="Link4" />
    <axis xyz="0 0 -1" />
    <limit lower="-0.8" upper="0.8" effort="1.6" velocity="5" />
  </joint>
  <link name="Link5">
    <inertial>
      <origin xyz="-0.00069753 -0.0032664 0.040879" rpy="0 0 0" />
      <mass value="0.23438" />
      <inertia ixx="6.5833E-05" ixy="4.682E-06" ixz="2.603E-07" iyy="8.781E-05" iyz="1.4416E-06" izz="7.0008E-05" />
    </inertial>
    <visual>
      <origin xyz="0 0 0" rpy="0 0 0" />
      <geometry>
        <mesh filename="package://sukinee_urdf/meshes/urdf_camera_gripper/Link5.STL" />
      </geometry>
      <material name="">
        <color rgba="0.89804 0.91765 0.92941 1" />
      </material>
    </visual>
    <collision>
      <origin xyz="0 0 0" rpy="0 0 0" />
      <geometry>
        <mesh filename="package://sukinee_urdf/meshes/urdf_camera_gripper/Link5.STL" />
      </geometry>
    </collision>
  </link>
  <joint name="Joint5" type="revolute">
    <origin xyz="-0.063304 -0.043146 -0.0245" rpy="1.5708 1.3765 3.112" />
    <parent link="Link4" />
    <child link="Link5" />
    <axis xyz="0 0 -1" />
    <limit lower="-0.8" upper="0.8" effort="1.6" velocity="5" />
  </joint>
  <link name="Link6">
    <inertial>
      <origin xyz="0.0024889 -0.0057192 0.037515" rpy="0 0 0" />
      <mass value="0.25842" />
      <inertia ixx="6.3275E-05" ixy="-2.4218E-05" ixz="-5.9557E-07" iyy="0.00010755" iyz="-4.046E-07" izz="0.00014859" />
    </inertial>
    <visual>
      <origin xyz="0 0 0" rpy="0 0 0" />
      <geometry>
        <mesh filename="package://sukinee_urdf/meshes/urdf_camera_gripper/Link6.STL" />
      </geometry>
      <material name="">
        <color rgba="0.69804 0.69804 0.69804 1" />
      </material>
    </visual>
    <collision>
      <origin xyz="0 0 0" rpy="0 0 0" />
      <geometry>
        <mesh filename="package://sukinee_urdf/meshes/urdf_camera_gripper/Link6.STL" />
      </geometry>
    </collision>
  </link>
  <joint name="Joint6" type="revolute">
    <origin xyz="0.003658 0.019663 0.045" rpy="1.5708 0.0055167 2.9577" />
    <parent link="Link5" />
    <child link="Link6" />
    <axis xyz="0 0 -1" />
    <limit lower="-2.1" upper="2.1" effort="1.6" velocity="5" />
  </joint>
  <link name="Link8">
    <inertial>
      <origin xyz="-1.3531E-16 -8.0214E-15 0.0030448" rpy="0 0 0" />
      <mass value="0.019614" />
      <inertia ixx="6.0759E-06" ixy="-1.3306E-05" ixz="7.577E-22" iyy="3.0348E-05" iyz="2.1085E-22" izz="3.6283E-05" />
    </inertial>
    <visual>
      <origin xyz="0 0 0" rpy="0 0 0" />
      <geometry>
        <mesh filename="package://sukinee_urdf/meshes/urdf_camera_gripper/Link8.STL" />
      </geometry>
      <material name="">
        <color rgba="0.89804 0.91765 0.92941 1" />
      </material>
    </visual>
    <collision>
      <origin xyz="0 0 0" rpy="0 0 0" />
      <geometry>
        <mesh filename="package://sukinee_urdf/meshes/urdf_camera_gripper/Link8.STL" />
      </geometry>
    </collision>
  </link>
  <joint name="Joint8" type="fixed">
    <origin xyz="1.7459E-05 0.00014898 0.075" rpy="0 0 0" />
    <parent link="Link6" />
    <child link="Link8" />
    <axis xyz="0 0 0" />
  </joint>
  <link name="Link7">
    <inertial>
      <origin xyz="1.993E-11 1.6042E-11 0.0062973" rpy="0 0 0" />
      <mass value="0.0027847" />
      <inertia ixx="1.8957E-07" ixy="-2.0185E-16" ixz="4.8123E-17" iyy="1.8957E-07" iyz="-5.3402E-17" izz="3.3854E-07" />
    </inertial>
    <visual>
      <origin xyz="0 0 0" rpy="0 0 0" />
      <geometry>
        <mesh filename="package://sukinee_urdf/meshes/urdf_camera_gripper/Link7.STL" />
      </geometry>
      <material name="">
        <color rgba="0.69804 0.69804 0.69804 1" />
      </material>
    </visual>
    <collision>
      <origin xyz="0 0 0" rpy="0 0 0" />
      <geometry>
        <mesh filename="package://sukinee_urdf/meshes/urdf_camera_gripper/Link7.STL" />
      </geometry>
    </collision>
  </link>
  <joint name="Joint7" type="revolute">
    <origin xyz="1.7459E-05 0.00014898 0.058" rpy="0 0 0" />
    <parent link="Link6" />
    <child link="Link7" />
    <axis xyz="0 0 -1" />
    <limit lower="0" upper="1.57" effort="1.6" velocity="5" />
  </joint>
  <link name="Link_r">
    <inertial>
      <origin xyz="0.0089236 0.0037835 -0.0070751" rpy="0 0 0" />
      <mass value="0.034938" />
      <inertia ixx="8.4376E-06" ixy="1.4671E-08" ixz="-6.1418E-07" iyy="9.0041E-06" iyz="-2.1554E-08" izz="5.2223E-06" />
    </inertial>
    <visual>
      <origin xyz="0 0 0" rpy="0 0 0" />
      <geometry>
        <mesh filename="package://sukinee_urdf/meshes/urdf_camera_gripper/Link_r.STL" />
      </geometry>
      <material name="">
        <color rgba="0.69804 0.69804 0.69804 1" />
      </material>
    </visual>
    <collision>
      <origin xyz="0 0 0" rpy="0 0 0" />
      <geometry>
        <mesh filename="package://sukinee_urdf/meshes/urdf_camera_gripper/Link_r.STL" />
      </geometry>
    </collision>
  </link>
  <joint name="right_finger" type="prismatic">
    <origin xyz="0.037984 0.016907 0.083123" rpy="1.5708 -1.5384 -1.1551" />
    <parent link="Link6" />
    <child link="Link_r" />
    <axis xyz="0 0 1" />
    <limit lower="0" upper="0.04" effort="1" velocity="0.02" />
    <mimic joint="Joint7" multiplier="0.025" offset="0" />
  </joint>
  <link name="Link_l">
    <inertial>
      <origin xyz="-0.0091526 -0.0032817 -0.0070751" rpy="0 0 0" />
      <mass value="0.034938" />
      <inertia ixx="8.4419E-06" ixy="5.116E-08" ixz="6.1429E-07" iyy="8.9999E-06" iyz="-1.8265E-08" izz="5.2223E-06" />
    </inertial>
    <visual>
      <origin xyz="0 0 0" rpy="0 0 0" />
      <geometry>
        <mesh filename="package://sukinee_urdf/meshes/urdf_camera_gripper/Link_l.STL" />
      </geometry>
      <material name="">
        <color rgba="0.69804 0.69804 0.69804 1" />
      </material>
    </visual>
    <collision>
      <origin xyz="0 0 0" rpy="0 0 0" />
      <geometry>
        <mesh filename="package://sukinee_urdf/meshes/urdf_camera_gripper/Link_l.STL" />
      </geometry>
    </collision>
  </link>
  <joint name="left_finger" type="prismatic">
    <origin xyz="-0.037949 -0.016609 0.083123" rpy="1.5708 1.5384 1.9865" />
    <parent link="Link6" />
    <child link="Link_l" />
    <axis xyz="0 0 1" />
    <limit lower="0" upper="0.04" effort="1" velocity="0.02" />
    <mimic joint="Joint7" multiplier="0.025" offset="0" />
  </joint>
  <link name="tool0" />
  <joint name="tool0_fixed_joint" type="fixed">
    <origin xyz="-0.000737 -0.000386 0.040000" rpy="0 0 0" />
    <parent link="Link8" />
    <child link="tool0" />
  </joint>
</robot>