<?xml version="1.0" encoding="utf-8"?>
<!-- This URDF was automatically created by SolidWorks to URDF Exporter! Originally created by Stephen Brawner (brawner@gmail.com) 
     Commit Version: 1.6.0-4-g7f85cfe  Build Version: 1.6.7995.38578
     For more information, please see http://wiki.ros.org/sw_urdf_exporter -->
<robot
  name="sukinee_urdf">
  <link
    name="base_link">
    <inertial>
      <origin
        xyz="-9.27159793573523E-05 5.84334903300024E-05 0.0131634742942032"
        rpy="0 0 0" />
      <mass
        value="0.276557659513136" />
      <inertia
        ixx="0.000306944214419235"
        ixy="-2.62966486226292E-05"
        ixz="-2.17057678389435E-07"
        iyy="0.00019619720224458"
        iyz="-1.11233404518986E-06"
        izz="0.000381711312546233" />
    </inertial>
    <visual>
      <origin
        xyz="0 0 0"
        rpy="0 0 0" />
      <geometry>
        <mesh
          filename="package://sukinee_urdf/meshes/base_link.STL" />
      </geometry>
      <material
        name="">
        <color
          rgba="1 1 1 1" />
      </material>
    </visual>
    <collision>
      <origin
        xyz="0 0 0"
        rpy="0 0 0" />
      <geometry>
        <mesh
          filename="package://sukinee_urdf/meshes/base_link.STL" />
      </geometry>
    </collision>
  </link>
  <link
    name="Link1">
    <inertial>
      <origin
        xyz="0.00328193566941784 -0.00101264174932876 0.0341645293592959"
        rpy="0 0 0" />
      <mass
        value="0.173424729959474" />
      <inertia
        ixx="8.50037683173789E-05"
        ixy="2.28577329805091E-07"
        ixz="-7.19620303243764E-07"
        iyy="7.01795557782873E-05"
        iyz="-1.21785758387906E-07"
        izz="8.92996495432085E-05" />
    </inertial>
    <visual>
      <origin
        xyz="0 0 0"
        rpy="0 0 0" />
      <geometry>
        <mesh
          filename="package://sukinee_urdf/meshes/Link1.STL" />
      </geometry>
      <material
        name="">
        <color
          rgba="1 1 1 1" />
      </material>
    </visual>
    <collision>
      <origin
        xyz="0 0 0"
        rpy="0 0 0" />
      <geometry>
        <mesh
          filename="package://sukinee_urdf/meshes/Link1.STL" />
      </geometry>
    </collision>
  </link>
  <joint
    name="Joint1"
    type="continuous">
    <origin
      xyz="-4.5606E-05 -0.00029999 0.051399"
      rpy="0 0 0" />
    <parent
      link="base_link" />
    <child
      link="Link1" />
    <axis
      xyz="0 0 1" />
    <limit
      effort="5"
      velocity="3.14" />
  </joint>
  <link
    name="Link2">
    <inertial>
      <origin
        xyz="0.163147205394747 0.0077249837082756 -0.0251647837081496"
        rpy="0 0 0" />
      <mass
        value="0.49221073789159" />
      <inertia
        ixx="0.00013320567604932"
        ixy="-1.90333861615628E-05"
        ixz="-2.02132460329359E-05"
        iyy="0.00146041125210994"
        iyz="-3.49082300685114E-07"
        izz="0.00147443591285137" />
    </inertial>
    <visual>
      <origin
        xyz="0 0 0"
        rpy="0 0 0" />
      <geometry>
        <mesh
          filename="package://sukinee_urdf/meshes/Link2.STL" />
      </geometry>
      <material
        name="">
        <color
          rgba="1 1 1 1" />
      </material>
    </visual>
    <collision>
      <origin
        xyz="0 0 0"
        rpy="0 0 0" />
      <geometry>
        <mesh
          filename="package://sukinee_urdf/meshes/Link2.STL" />
      </geometry>
    </collision>
  </link>
  <joint
    name="Joint2"
    type="revolute">
    <origin
      xyz="0.0068769 -0.027546 0.042346"
      rpy="-1.5708 0 3.1416" />
    <parent
      link="Link1" />
    <child
      link="Link2" />
    <axis
      xyz="0 0 1" />
    <limit
      lower="-0.79"
      upper="0.79"
      effort="5"
      velocity="3.14" />
  </joint>
  <link
    name="Link3">
    <inertial>
      <origin
        xyz="-0.123533258510765 -0.0531477412867997 -0.0289818543594236"
        rpy="0 0 0" />
      <mass
        value="0.342921181307181" />
      <inertia
        ixx="8.97920455274715E-05"
        ixy="-5.81304856828259E-05"
        ixz="-1.06742108487144E-05"
        iyy="0.00076637159477087"
        iyz="-9.66346038777982E-07"
        izz="0.00078459383677109" />
    </inertial>
    <visual>
      <origin
        xyz="0 0 0"
        rpy="0 0 0" />
      <geometry>
        <mesh
          filename="package://sukinee_urdf/meshes/Link3.STL" />
      </geometry>
      <material
        name="">
        <color
          rgba="1 1 1 1" />
      </material>
    </visual>
    <collision>
      <origin
        xyz="0 0 0"
        rpy="0 0 0" />
      <geometry>
        <mesh
          filename="package://sukinee_urdf/meshes/Link3.STL" />
      </geometry>
    </collision>
  </link>
  <joint
    name="Joint3"
    type="revolute">
    <origin
      xyz="0.26443 0.0031418 0.0039907"
      rpy="0 0 0" />
    <parent
      link="Link2" />
    <child
      link="Link3" />
    <axis
      xyz="0 0 1" />
    <limit
      lower="-0.79"
      upper="0.79"
      effort="5"
      velocity="3.14" />
  </joint>
  <link
    name="Link4">
    <inertial>
      <origin
        xyz="0.0325057327109481 0.0348518868836431 -0.0264977574735537"
        rpy="0 0 0" />
      <mass
        value="0.0535059280721223" />
      <inertia
        ixx="3.35516541099526E-05"
        ixy="-9.36823847263875E-06"
        ixz="-1.44258751379024E-07"
        iyy="4.45006403501621E-05"
        iyz="9.87407338332834E-08"
        izz="3.33930480114162E-05" />
    </inertial>
    <visual>
      <origin
        xyz="0 0 0"
        rpy="0 0 0" />
      <geometry>
        <mesh
          filename="package://sukinee_urdf/meshes/Link4.STL" />
      </geometry>
      <material
        name="">
        <color
          rgba="1 1 1 1" />
      </material>
    </visual>
    <collision>
      <origin
        xyz="0 0 0"
        rpy="0 0 0" />
      <geometry>
        <mesh
          filename="package://sukinee_urdf/meshes/Link4.STL" />
      </geometry>
    </collision>
  </link>
  <joint
    name="Joint4"
    type="revolute">
    <origin
      xyz="-0.24836 -0.068439 -0.0072675"
      rpy="0 0 3.1416" />
    <parent
      link="Link3" />
    <child
      link="Link4" />
    <axis
      xyz="0 0 1" />
    <limit
      lower="-0.79"
      upper="0.79"
      effort="1.6"
      velocity="3.14" />
  </joint>
  <link
    name="Link5">
    <inertial>
      <origin
        xyz="-0.0056734168385737 -6.71961845820235E-05 0.0360575266624941"
        rpy="0 0 0" />
      <mass
        value="0.042177959365491" />
      <inertia
        ixx="1.36297549043679E-05"
        ixy="-6.35878998308485E-08"
        ixz="4.27272196782813E-07"
        iyy="1.20691454899998E-05"
        iyz="-1.72009298073699E-08"
        izz="1.47091693168405E-05" />
    </inertial>
    <visual>
      <origin
        xyz="0 0 0"
        rpy="0 0 0" />
      <geometry>
        <mesh
          filename="package://sukinee_urdf/meshes/Link5.STL" />
      </geometry>
      <material
        name="">
        <color
          rgba="1 1 1 1" />
      </material>
    </visual>
    <collision>
      <origin
        xyz="0 0 0"
        rpy="0 0 0" />
      <geometry>
        <mesh
          filename="package://sukinee_urdf/meshes/Link5.STL" />
      </geometry>
    </collision>
  </link>
  <joint
    name="Joint5"
    type="revolute">
    <origin
      xyz="0.061641 0.045136 -0.024175"
      rpy="1.5708 0 0" />
    <parent
      link="Link4" />
    <child
      link="Link5" />
    <axis
      xyz="0 0 1" />
    <limit
      lower="-0.79"
      upper="0.79"
      effort="1.6"
      velocity="3.14" />
  </joint>
  <link
    name="Link6">
    <inertial>
      <origin
        xyz="0.00554378475155647 -0.0150082526027543 0.0428267890047218"
        rpy="0 0 0" />
      <mass
        value="0.10618748414872" />
      <inertia
        ixx="3.01056257940198E-05"
        ixy="-3.61927922989586E-05"
        ixz="-1.26983678010513E-06"
        iyy="9.61417818647484E-05"
        iyz="-1.31809647850692E-06"
        izz="0.000117560025307442" />
    </inertial>
    <visual>
      <origin
        xyz="0 0 0"
        rpy="0 0 0" />
      <geometry>
        <mesh
          filename="package://sukinee_urdf/meshes/Link6.STL" />
      </geometry>
      <material
        name="">
        <color
          rgba="1 1 1 1" />
      </material>
    </visual>
    <collision>
      <origin
        xyz="0 0 0"
        rpy="0 0 0" />
      <geometry>
        <mesh
          filename="package://sukinee_urdf/meshes/Link6.STL" />
      </geometry>
    </collision>
  </link>
  <joint
    name="Joint6"
    type="continuous">
    <origin
      xyz="0.019993 -0.00056516 0.044999"
      rpy="1.5708 0 1.5708" />
    <parent
      link="Link5" />
    <child
      link="Link6" />
    <axis
      xyz="0 0 1" />
    <limit
      lower="-0.79"
      upper="0.79"
      effort="1.6"
      velocity="3.14" />
  </joint>
  <link
    name="Link8">
    <inertial>
      <origin
        xyz="5.85779128040032E-06 1.2548200144985E-05 -0.000913384881462739"
        rpy="0 0 0" />
      <mass
        value="0.0685515728356248" />
      <inertia
        ixx="6.30938201003045E-05"
        ixy="-1.29294803104063E-06"
        ixz="-1.94225120141591E-08"
        iyy="6.15063978466288E-07"
        iyz="-8.70188873709462E-07"
        izz="6.33405513208031E-05" />
    </inertial>
    <visual>
      <origin
        xyz="0 0 0"
        rpy="0 0 0" />
      <geometry>
        <mesh
          filename="package://sukinee_urdf/meshes/Link8.STL" />
      </geometry>
      <material
        name="">
        <color
          rgba="0.647058823529412 0.619607843137255 0.588235294117647 1" />
      </material>
    </visual>
    <collision>
      <origin
        xyz="0 0 0"
        rpy="0 0 0" />
      <geometry>
        <mesh
          filename="package://sukinee_urdf/meshes/Link8.STL" />
      </geometry>
    </collision>
  </link>
  <joint
    name="Joint8"
    type="fixed">
    <origin
      xyz="-0.0011196 0.00014947 0.074992"
      rpy="0 0 -1.1345" />
    <parent
      link="Link6" />
    <child
      link="Link8" />
    <axis
      xyz="0 0 0" />
  </joint>
  <link
    name="Link7">
    <inertial>
      <origin
        xyz="-8.68739260867571E-05 3.67829469383185E-08 0.00572996261787687"
        rpy="0 0 0" />
      <mass
        value="0.0056954950921208" />
      <inertia
        ixx="4.10624607722094E-07"
        ixy="-3.13422376163062E-14"
        ixz="-4.88242668047372E-09"
        iyy="4.10550583591966E-07"
        iyz="2.06724684264108E-12"
        izz="7.32581872233262E-07" />
    </inertial>
    <visual>
      <origin
        xyz="0 0 0"
        rpy="0 0 0" />
      <geometry>
        <mesh
          filename="package://sukinee_urdf/meshes/Link7.STL" />
      </geometry>
      <material
        name="">
        <color
          rgba="1 1 1 1" />
      </material>
    </visual>
    <collision>
      <origin
        xyz="0 0 0"
        rpy="0 0 0" />
      <geometry>
        <mesh
          filename="package://sukinee_urdf/meshes/Link7.STL" />
      </geometry>
    </collision>
  </link>
  <joint
    name="Joint7"
    type="revolute">
    <origin
      xyz="0.00010901 0.00023352 -0.016998"
      rpy="0 0 1.1345" />
    <parent
      link="Link8" />
    <child
      link="Link7" />
    <axis
      xyz="0 0 1" />
    <limit
      lower="-0.79"
      upper="0.79"
      effort="1.6"
      velocity="3.14" />
  </joint>
  <link
    name="Link9">
    <inertial>
      <origin
        xyz="-0.0243860514000653 0.000940994416315399 0.0968274848139791"
        rpy="0 0 0" />
      <mass
        value="0.0514991247749255" />
      <inertia
        ixx="8.28736180563144E-06"
        ixy="-7.26191574978187E-08"
        ixz="-2.42329844551363E-06"
        iyy="2.19576619782527E-05"
        iyz="2.17053480223994E-12"
        izz="2.34373850902803E-05" />
    </inertial>
    <visual>
      <origin
        xyz="0 0 0"
        rpy="0 0 0" />
      <geometry>
        <mesh
          filename="package://sukinee_urdf/meshes/Link9.STL" />
      </geometry>
      <material
        name="">
        <color
          rgba="0.898039215686275 0.917647058823529 0.929411764705882 1" />
      </material>
    </visual>
    <collision>
      <origin
        xyz="0 0 0"
        rpy="0 0 0" />
      <geometry>
        <mesh
          filename="package://sukinee_urdf/meshes/Link9.STL" />
      </geometry>
    </collision>
  </link>
  <joint
    name="right_finger"
    type="prismatic">
    <origin
      xyz="-0.00090214 -0.041949 0.0075419"
      rpy="-0.41597 1.5556 1.1345" />
    <parent
      link="Link8" />
    <child
      link="Link9" />
    <axis
      xyz="0 0 1" />
    <limit
      lower="-0.006"
      upper="0.006"
      effort="1"
      velocity="0.05" />
    <mimic
      joint="Joint7"
      multiplier="0.02"
      offset="0" />
  </joint>
  <link
    name="Link10">
    <inertial>
      <origin
        xyz="0.0243860656141254 -0.00109398804918623 0.0968274848182184"
        rpy="0 0 0" />
      <mass
        value="0.0514991248787955" />
      <inertia
        ixx="8.28736387357228E-06"
        ixy="-7.28109951429884E-08"
        ixz="2.42329844302306E-06"
        iyy="2.1957659945586E-05"
        iyz="3.18400441671419E-11"
        izz="2.34373851160649E-05" />
    </inertial>
    <visual>
      <origin
        xyz="0 0 0"
        rpy="0 0 0" />
      <geometry>
        <mesh
          filename="package://sukinee_urdf/meshes/Link10.STL" />
      </geometry>
      <material
        name="">
        <color
          rgba="1 1 1 1" />
      </material>
    </visual>
    <collision>
      <origin
        xyz="0 0 0"
        rpy="0 0 0" />
      <geometry>
        <mesh
          filename="package://sukinee_urdf/meshes/Link10.STL" />
      </geometry>
    </collision>
  </link>
  <joint
    name="left_finger"
    type="prismatic">
    <origin
      xyz="0.00079796 0.041726 0.0087023"
      rpy="-2.7256 -1.5556 -2.0071" />
    <parent
      link="Link8" />
    <child
      link="Link10" />
    <axis
      xyz="0 0 1" />
    <limit
      lower="-0.006"
      upper="0.006"
      effort="1"
      velocity="0.05" />
    <mimic
      joint="Joint7"
      multiplier="0.02"
      offset="0" />
  </joint>
</robot>